Workbook

Sheet crono ejemplo
A1: N° | B1: Actividad | C1: Fecha | E1: Aspectos generales de planificación | N1: Impacto Real (%) | O1: Avance Real (%) | Q1: Área | AE1: % Completado Tarea | AF1: Valor Ganado | AG1: Valor Ganado (%) | AH1: Valor Ganado Acum (%)
E2: Dias | F2: HH | G2: % Impacto | H2: % Avance | I2: Esfuerzo (HH) | L2: Costo (UF) | Q2: Jefe de Proyecto | V2: Documentación | Y2: Investigación | AB2: Desarrollo
C3: Inicio | D3: Termino | I3: Unit. | J3: Acum. | K3: % De uso | L3: Unit. | M3: Acum. | P3: % De uso | Q3: % dedic | R3: HH esfuerzo | S3: Rol | T3: Valor HH (UF) | U3: Costo (UF) | V3: % dedic | W3: HH esfuerzo | X3: Costo (UF) | Y3: % dedic | Z3: HH esfuerzo | AA3: Costo (UF) | AB3: % dedic | AC3: HH esfuerzo | AD3: Costo (UF)
A4: 1 | B4: Fase de Inicio | C4: 44656 | D4: 44670 | E4: =_xludf.DAYs(D4,C4)+1 -> #NAME? | F4: =SUM(F5,F7) -> 26 | G4: =SUM(G5,G7) -> 0.029511918 | I4: =SUM(I5,I7) -> #REF! | J4: =I4 -> #REF! | K4: =SUM(K5,K7) -> #REF! | L4: =SUM(L5,L7) -> #REF! | M4: =L4 -> #REF! | P4: =M4/$M$93 -> #REF!
A5: 1.1 | B5: Relevamiento inicial del Proyecto | C5: 44656 | D5: 44656 | E5: =_xludf.DAYs(D5,C5)+1 -> #NAME? | F5: =SUM(F6) -> 1 | G5: =G6 -> 0.0011350738 | I5: =SUM(I6) -> #REF! | J5: =J6 -> #REF! | K5: =SUM(J6) -> #REF! | L5: =L6 -> #REF! | M5: =L5 -> #REF! | P5: =SUM(P6) -> #REF!
A6: 1.1.1 | B6: Definición de Roles | C6: 44656 | D6: 44656 | E6: =_xludf.DAYs(D6,C6)+1 -> #NAME? | F6: 1 | G6: =F6/F105 -> 0.0011350738 | H6: =G6 -> 0.0011350738 | I6: =SUM(R6,W6,Z6,AC6) -> #REF! | J6: =I6 -> #REF! | K6: =J6/$J$104 -> #REF! | L6: =SUM(U6,X6,AA6,AD6) -> #REF! | M6: =L6 -> #REF! | N6: =G6*AE6 -> 0 | O6: =N6 -> 0 | P6: =M6/$M$93 -> #REF! | Q6: =R6/F6 -> 1 | R6: 1 | S6: L | T6: =IF(S6="L",0.68,IF(S6="JP",0.57,IF(S6="JI",0.57,IF(S6="JD",0.57,IF(S6="P",0.24,IF(S6="I",0.12,IF(S6="D",0.13))))))) -> 0.68 | U6: =T6*R6 -> 0.68 | V6: =W6/F6 -> #REF! | W6: ='CD R Documentación'!O7+'CD R Documentación'!T7+'CD R Documentación'!Y7+'CD R Documentación'!AD7+'CD R Documentación'!AI7+'CD R Documentación'!AN7+#REF! -> #REF! | X6: ='CD R Documentación'!R7+'CD R Documentación'!W7+'CD R Documentación'!AB7+'CD R Documentación'!AG7+'CD R Documentación'!AL7+'CD R Documentación'!AQ7+#REF! -> #REF! | Y6: =Z6/F6 -> 0 | Z6: ='CD R Investigación'!P7+'CD R Investigación'!U7+'CD R Investigación'!Z7+'CD R Investigación'!AE7+'CD R Investigación'!AJ7+'CD R Investigación'!AO7+'CD R Investigación'!AT7+'CD R Investigación'!AY7 -> 0 | AA6: ='CD R Investigación'!S7+'CD R Investigación'!X7+'CD R Investigación'!AC7+'CD R Investigación'!AH7+'CD R Investigación'!AM7+'CD R Investigación'!AR7+'CD R Investigación'!AW7+'CD R Investigación'!BB7 -> 0 | AB6: =AC6/F6 -> #REF! | AC6: ='CD R Desarrollo'!P7+'CD R Desarrollo'!U7+'CD R Desarrollo'!Z7+'CD R Desarrollo'!AE7+'CD R Desarrollo'!AJ7+'CD R Desarrollo'!AO7+#REF!+#REF! -> #REF! | AD6: ='CD R Desarrollo'!S7+'CD R Desarrollo'!X7+'CD R Desarrollo'!AC7+'CD R Desarrollo'!AH7+'CD R Desarrollo'!AM7+'CD R Desarrollo'!AR7+#REF!+#REF! -> #REF! | AE6: 0 | AF6: ='PL Cronograma detallado'!L40*AE6 -> 0 | AG6: =AF6/'PL Cronograma detallado'!M257 -> #DIV/0! | AH6: =AG6 -> #DIV/0!
A7: 1.2 | B7: Gestión del Alcance | C7: 44656 | D7: 44662 | E7: =_xludf.DAYs(D7,C7)+1 -> #NAME? | F7: =SUM(F8:F19) -> 25 | G7: =SUM(G8:G19) -> 0.028376844 | H7: =SUM(H6,G7) -> 0.029511918 | I7: =SUM(I8:I19) -> #REF! | J7: =SUM(I7,J5) -> #REF! | K7: =SUM(K8:K16) -> #REF! | L7: =SUM(L8:L19) -> #REF! | M7: =SUM(L7,M5) -> #REF! | P7: =M7/$M$93 -> #REF!
A8: 1.2.1 | B8: Organización de grupos de Trabajo | C8: 44657 | D8: 44657 | E8: =_xludf.DAYs(D8,C8)+1 -> #NAME? | F8: 1 | G8: =F8/F$105 -> 0.0011350738 | H8: =SUM(H6,G8) -> 0.0022701476 | I8: =SUM(R8,W8,Z8,AC8) -> #REF! | J8: =SUM(I8,J6) -> #REF! | K8: =J8/$J$104 -> #REF! | L8: =SUM(U8,X8,AA8,AD8) -> #REF! | M8: =SUM(L8,M6) -> #REF! | N8: =G8*AE8 -> 0.0011350738 | O8: =SUM(N8,O6) -> 0.0011350738 | P8: =M8/$M$93 -> #REF! | Q8: =R8/F8 -> 1 | R8: 1 | S8: L | T8: =IF(S8="L",0.68,IF(S8="JP",0.57,IF(S8="JI",0.57,IF(S8="JD",0.57,IF(S8="P",0.24,IF(S8="I",0.12,IF(S8="D",0.13))))))) -> 0.68 | U8: =T8*R8 -> 0.68 | V8: =W8/F8 -> #REF! | W8: ='CD R Documentación'!O9+'CD R Documentación'!T9+'CD R Documentación'!Y9+'CD R Documentación'!AD9+'CD R Documentación'!AI9+'CD R Documentación'!AN9+#REF! -> #REF! | X8: ='CD R Documentación'!R9+'CD R Documentación'!W9+'CD R Documentación'!AB9+'CD R Documentación'!AG9+'CD R Documentación'!AL9+'CD R Documentación'!AQ9+#REF! -> #REF! | Y8: =Z8/F8 -> 3 | Z8: ='CD R Investigación'!P9+'CD R Investigación'!U9+'CD R Investigación'!Z9+'CD R Investigación'!AE9+'CD R Investigación'!AJ9+'CD R Investigación'!AO9+'CD R Investigación'!AT9+'CD R Investigación'!AY9 -> 3 | AA8: ='CD R Investigación'!S9+'CD R Investigación'!X9+'CD R Investigación'!AC9+'CD R Investigación'!AH9+'CD R Investigación'!AM9+'CD R Investigación'!AR9+'CD R Investigación'!AW9+'CD R Investigación'!BB9 -> 1.32 | AB8: =AC8/F8 -> #REF! | AC8: ='CD R Desarrollo'!P9+'CD R Desarrollo'!U9+'CD R Desarrollo'!Z9+'CD R Desarrollo'!AE9+'CD R Desarrollo'!AJ9+'CD R Desarrollo'!AO9+#REF!+#REF! -> #REF! | AD8: ='CD R Desarrollo'!S9+'CD R Desarrollo'!X9+'CD R Desarrollo'!AC9+'CD R Desarrollo'!AH9+'CD R Desarrollo'!AM9+'CD R Desarrollo'!AR9+#REF!+#REF! -> #REF! | AE8: 1 | AF8: ='PL Cronograma detallado'!L42*AE8 -> 9.67 | AG8: =AF8/'PL Cronograma detallado'!M$257 -> #DIV/0! | AH8: =AG8+AH6 -> #DIV/0!
A9: 1.2.2 | B9: Definición de Enfoques y Justificación | C9: 44657 | D9: 44658 | E9: =_xludf.DAYs(D9,C9)+1 -> #NAME? | F9: 2 | G9: =F9/F$105 -> 0.0022701476 | H9: =SUM(H8,G9) -> 0.0045402951 | I9: =SUM(R9,W9,Z9,AC9) -> #REF! | J9: =SUM(I9,J8) -> #REF! | K9: =J9/$J$104 -> #REF! | L9: =SUM(U9,X9,AA9,AD9) -> #REF! | M9: =SUM(L9,M8) -> #REF! | N9: =G9*AE9 -> 0.0022701476 | O9: =SUM(N9,O8) -> 0.0034052213 | P9: =M9/$M$93 -> #REF! | Q9: =R9/F9 -> 0.5 | R9: 1 | S9: L | T9: =IF(S9="L",0.68,IF(S9="JP",0.57,IF(S9="JI",0.57,IF(S9="JD",0.57,IF(S9="P",0.24,IF(S9="I",0.12,IF(S9="D",0.13))))))) -> 0.68 | U9: =T9*R9 -> 0.68 | V9: =W9/F9 -> #REF! | W9: ='CD R Documentación'!O10+'CD R Documentación'!T10+'CD R Documentación'!Y10+'CD R Documentación'!AD10+'CD R Documentación'!AI10+'CD R Documentación'!AN10+#REF! -> #REF! | X9: ='CD R Documentación'!R10+'CD R Documentación'!W10+'CD R Documentación'!AB10+'CD R Documentación'!AG10+'CD R Documentación'!AL10+'CD R Documentación'!AQ10+#REF! -> #REF! | Y9: =Z9/F9 -> 0 | Z9: ='CD R Investigación'!P10+'CD R Investigación'!U10+'CD R Investigación'!Z10+'CD R Investigación'!AE10+'CD R Investigación'!AJ10+'CD R Investigación'!AO10+'CD R Investigación'!AT10+'CD R Investigación'!AY10 -> 0 | AA9: ='CD R Investigación'!S10+'CD R Investigación'!X10+'CD R Investigación'!AC10+'CD R Investigación'!AH10+'CD R Investigación'!AM10+'CD R Investigación'!AR10+'CD R Investigación'!AW10+'CD R Investigación'!BB10 -> 0 | AB9: =AC9/F9 -> #REF! | AC9: ='CD R Desarrollo'!P10+'CD R Desarrollo'!U10+'CD R Desarrollo'!Z10+'CD R Desarrollo'!AE10+'CD R Desarrollo'!AJ10+'CD R Desarrollo'!AO10+#REF!+#REF! -> #REF! | AD9: ='CD R Desarrollo'!S10+'CD R Desarrollo'!X10+'CD R Desarrollo'!AC10+'CD R Desarrollo'!AH10+'CD R Desarrollo'!AM10+'CD R Desarrollo'!AR10+#REF!+#REF! -> #REF! | AE9: 1 | AF9: ='PL Cronograma detallado'!L58*AE9 -> 49.43 | AG9: =AF9/'PL Cronograma detallado'!M$257 -> #DIV/0! | AH9: =AG9+AH8 -> #DIV/0!
A10: 1.2.3 | B10: Establecer Alcances y Limitaciones | C10: 44657 | D10: 44658 | E10: =_xludf.DAYs(D10,C10)+1 -> #NAME? | F10: 2 | G10: =F10/F$105 -> 0.0022701476 | H10: =SUM(H9,G10) -> 0.0068104427 | I10: =SUM(R10,W10,Z10,AC10) -> #REF! | J10: =SUM(I10,J9) -> #REF! | K10: =J10/$J$104 -> #REF! | L10: =SUM(U10,X10,AA10,AD10) -> #REF! | M10: =SUM(L10,M9) -> #REF! | N10: =G10*AE10 -> 0.0022701476 | O10: =SUM(N10,O9) -> 0.0056753689 | P10: =M10/$M$93 -> #REF! | Q10: =R10/F10 -> 0.5 | R10: 1 | S10: L | T10: =IF(S10="L",0.68,IF(S10="JP",0.57,IF(S10="JI",0.57,IF(S10="JD",0.57,IF(S10="P",0.24,IF(S10="I",0.12,IF(S10="D",0.13))))))) -> 0.68 | U10: =T10*R10 -> 0.68 | V10: =W10/F10 -> #REF! | W10: ='CD R Documentación'!O11+'CD R Documentación'!T11+'CD R Documentación'!Y11+'CD R Documentación'!AD11+'CD R Documentación'!AI11+'CD R Documentación'!AN11+#REF! -> #REF! | X10: ='CD R Documentación'!R11+'CD R Documentación'!W11+'CD R Documentación'!AB11+'CD R Documentación'!AG11+'CD R Documentación'!AL11+'CD R Documentación'!AQ11+#REF! -> #REF! | Y10: =Z10/F10 -> 1.5 | Z10: ='CD R Investigación'!P11+'CD R Investigación'!U11+'CD R Investigación'!Z11+'CD R Investigación'!AE11+'CD R Investigación'!AJ11+'CD R Investigación'!AO11+'CD R Investigación'!AT11+'CD R Investigación'!AY11 -> 3 | AA10: ='CD R Investigación'!S11+'CD R Investigación'!X11+'CD R Investigación'!AC11+'CD R Investigación'!AH11+'CD R Investigación'!AM11+'CD R Investigación'!AR11+'CD R Investigación'!AW11+'CD R Investigación'!BB11 -> 1.32 | AB10: =AC10/F10 -> #REF! | AC10: ='CD R Desarrollo'!P11+'CD R Desarrollo'!U11+'CD R Desarrollo'!Z11+'CD R Desarrollo'!AE11+'CD R Desarrollo'!AJ11+'CD R Desarrollo'!AO11+#REF!+#REF! -> #REF! | AD10: ='CD R Desarrollo'!S11+'CD R Desarrollo'!X11+'CD R Desarrollo'!AC11+'CD R Desarrollo'!AH11+'CD R Desarrollo'!AM11+'CD R Desarrollo'!AR11+#REF!+#REF! -> #REF! | AE10: 1 | AF10: ='PL Cronograma detallado'!L59*AE10 -> 34.27 | AG10: =AF10/'PL Cronograma detallado'!M$257 -> #DIV/0! | AH10: =AG10+AH9 -> #DIV/0!
A11: 1.2.4 | B11: Definir Metodologias | C11: 44657 | D11: 44660 | E11: =_xludf.DAYs(D11,C11)+1 -> #NAME? | F11: 2 | G11: =F11/F$105 -> 0.0022701476 | H11: =SUM(H10,G11) -> 0.0090805902 | I11: =SUM(R11,W11,Z11,AC11) -> #REF! | J11: =SUM(I11,J10) -> #REF! | K11: =J11/$J$104 -> #REF! | L11: =SUM(U11,X11,AA11,AD11) -> #REF! | M11: =SUM(L11,M10) -> #REF! | N11: =G11*AE11 -> 0.0022701476 | O11: =SUM(N11,O10) -> 0.0079455165 | P11: =M11/$M$93 -> #REF! | Q11: =R11/F11 -> 0.5 | R11: 1 | S11: L | T11: =IF(S11="L",0.68,IF(S11="JP",0.57,IF(S11="JI",0.57,IF(S11="JD",0.57,IF(S11="P",0.24,IF(S11="I",0.12,IF(S11="D",0.13))))))) -> 0.68 | U11: =T11*R11 -> 0.68 | V11: =W11/F11 -> #REF! | W11: ='CD R Documentación'!O12+'CD R Documentación'!T12+'CD R Documentación'!Y12+'CD R Documentación'!AD12+'CD R Documentación'!AI12+'CD R Documentación'!AN12+#REF! -> #REF! | X11: ='CD R Documentación'!R12+'CD R Documentación'!W12+'CD R Documentación'!AB12+'CD R Documentación'!AG12+'CD R Documentación'!AL12+'CD R Documentación'!AQ12+#REF! -> #REF! | Y11: =Z11/F11 -> 1 | Z11: ='CD R Investigación'!P12+'CD R Investigación'!U12+'CD R Investigación'!Z12+'CD R Investigación'!AE12+'CD R Investigación'!AJ12+'CD R Investigación'!AO12+'CD R Investigación'!AT12+'CD R Investigación'!AY12 -> 2 | AA11: ='CD R Investigación'!S12+'CD R Investigación'!X12+'CD R Investigación'!AC12+'CD R Investigación'!AH12+'CD R Investigación'!AM12+'CD R Investigación'!AR12+'CD R Investigación'!AW12+'CD R Investigación'!BB12 -> 0.88 | AB11: =AC11/F11 -> #REF! | AC11: ='CD R Desarrollo'!P12+'CD R Desarrollo'!U12+'CD R Desarrollo'!Z12+'CD R Desarrollo'!AE12+'CD R Desarrollo'!AJ12+'CD R Desarrollo'!AO12+#REF!+#REF! -> #REF! | AD11: ='CD R Desarrollo'!S12+'CD R Desarrollo'!X12+'CD R Desarrollo'!AC12+'CD R Desarrollo'!AH12+'CD R Desarrollo'!AM12+'CD R Desarrollo'!AR12+#REF!+#REF! -> #REF! | AE11: 1 | AF11: ='PL Cronograma detallado'!L60*AE11 -> 13.81 | AG11: =AF11/'PL Cronograma detallado'!M$257 -> #DIV/0! | AH11: =AG11+AH10 -> #DIV/0!
A12: 1.2.5 | B12: Definir Plan de Hitos | C12: 44657 | D12: 44657 | E12: =_xludf.DAYs(D12,C12)+1 -> #NAME? | F12: 1 | G12: =F12/F$105 -> 0.0011350738 | H12: =SUM(H11,G12) -> 0.010215664 | I12: =SUM(R12,W12,Z12,AC12) -> #REF! | J12: =SUM(I12,J11) -> #REF! | K12: =J12/$J$104 -> #REF! | L12: =SUM(U12,X12,AA12,AD12) -> #REF! | M12: =SUM(L12,M11) -> #REF! | N12: =G12*AE12 -> 0.0011350738 | O12: =SUM(N12,O11) -> 0.0090805902 | P12: =M12/$M$93 -> #REF! | Q12: =R12/F12 -> 1 | R12: 1 | S12: L | T12: =IF(S12="L",0.68,IF(S12="JP",0.57,IF(S12="JI",0.57,IF(S12="JD",0.57,IF(S12="P",0.24,IF(S12="I",0.12,IF(S12="D",0.13))))))) -> 0.68 | U12: =T12*R12 -> 0.68 | V12: =W12/F12 -> #REF! | W12: ='CD R Documentación'!O13+'CD R Documentación'!T13+'CD R Documentación'!Y13+'CD R Documentación'!AD13+'CD R Documentación'!AI13+'CD R Documentación'!AN13+#REF! -> #REF! | X12: ='CD R Documentación'!R13+'CD R Documentación'!W13+'CD R Documentación'!AB13+'CD R Documentación'!AG13+'CD R Documentación'!AL13+'CD R Documentación'!AQ13+#REF! -> #REF! | Y12: =Z12/F12 -> 1 | Z12: ='CD R Investigación'!P13+'CD R Investigación'!U13+'CD R Investigación'!Z13+'CD R Investigación'!AE13+'CD R Investigación'!AJ13+'CD R Investigación'!AO13+'CD R Investigación'!AT13+'CD R Investigación'!AY13 -> 1 | AA12: ='CD R Investigación'!S13+'CD R Investigación'!X13+'CD R Investigación'!AC13+'CD R Investigación'!AH13+'CD R Investigación'!AM13+'CD R Investigación'!AR13+'CD R Investigación'!AW13+'CD R Investigación'!BB13 -> 0.44 | AB12: =AC12/F12 -> #REF! | AC12: ='CD R Desarrollo'!P13+'CD R Desarrollo'!U13+'CD R Desarrollo'!Z13+'CD R Desarrollo'!AE13+'CD R Desarrollo'!AJ13+'CD R Desarrollo'!AO13+#REF!+#REF! -> #REF! | AD12: ='CD R Desarrollo'!S13+'CD R Desarrollo'!X13+'CD R Desarrollo'!AC13+'CD R Desarrollo'!AH13+'CD R Desarrollo'!AM13+'CD R Desarrollo'!AR13+#REF!+#REF! -> #REF! | AE12: 1 | AF12: ='PL Cronograma detallado'!L62*AE12 -> 19.67 | AG12: =AF12/'PL Cronograma detallado'!M$257 -> #DIV/0! | AH12: =AG12+AH11 -> #DIV/0!
A13: 1.2.6 | B13: Elaborar Cronograma | C13: 44657 | D13: 44660 | E13: =_xludf.DAYs(D13,C13)+1 -> #NAME? | F13: 5 | G13: =F13/F$105 -> 0.0056753689 | H13: =SUM(H12,G13) -> 0.015891033 | I13: =SUM(R13,W13,Z13,AC13) -> #REF! | J13: =SUM(I13,J12) -> #REF! | K13: =J13/$J$104 -> #REF! | L13: =SUM(U13,X13,AA13,AD13) -> #REF! | M13: =SUM(L13,M12) -> #REF! | N13: =G13*AE13 -> 0.0056753689 | O13: =SUM(N13,O12) -> 0.014755959 | P13: =M13/$M$93 -> #REF! | Q13: =R13/F13 -> 0.2 | R13: 1 | S13: L | T13: =IF(S13="L",0.68,IF(S13="JP",0.57,IF(S13="JI",0.57,IF(S13="JD",0.57,IF(S13="P",0.24,IF(S13="I",0.12,IF(S13="D",0.13))))))) -> 0.68 | U13: =T13*R13 -> 0.68 | V13: =W13/F13 -> #REF! | W13: ='CD R Documentación'!O14+'CD R Documentación'!T14+'CD R Documentación'!Y14+'CD R Documentación'!AD14+'CD R Documentación'!AI14+'CD R Documentación'!AN14+#REF! -> #REF! | X13: ='CD R Documentación'!R14+'CD R Documentación'!W14+'CD R Documentación'!AB14+'CD R Documentación'!AG14+'CD R Documentación'!AL14+'CD R Documentación'!AQ14+#REF! -> #REF! | Y13: =Z13/F13 -> 0.8 | Z13: ='CD R Investigación'!P14+'CD R Investigación'!U14+'CD R Investigación'!Z14+'CD R Investigación'!AE14+'CD R Investigación'!AJ14+'CD R Investigación'!AO14+'CD R Investigación'!AT14+'CD R Investigación'!AY14 -> 4 | AA13: ='CD R Investigación'!S14+'CD R Investigación'!X14+'CD R Investigación'!AC14+'CD R Investigación'!AH14+'CD R Investigación'!AM14+'CD R Investigación'!AR14+'CD R Investigación'!AW14+'CD R Investigación'!BB14 -> 1.76 | AB13: =AC13/F13 -> #REF! | AC13: ='CD R Desarrollo'!P14+'CD R Desarrollo'!U14+'CD R Desarrollo'!Z14+'CD R Desarrollo'!AE14+'CD R Desarrollo'!AJ14+'CD R Desarrollo'!AO14+#REF!+#REF! -> #REF! | AD13: ='CD R Desarrollo'!S14+'CD R Desarrollo'!X14+'CD R Desarrollo'!AC14+'CD R Desarrollo'!AH14+'CD R Desarrollo'!AM14+'CD R Desarrollo'!AR14+#REF!+#REF! -> #REF! | AE13: 1 | AF13: ='PL Cronograma detallado'!L63*AE13 -> 7.65 | AG13: =AF13/'PL Cronograma detallado'!M$257 -> #DIV/0! | AH13: =AG13+AH12 -> #DIV/0!
A14: 1.2.7 | B14: Distribución del Esfuerzo | C14: 44658 | D14: 44659 | E14: =_xludf.DAYs(D14,C14)+1 -> #NAME? | F14: 4 | G14: =F14/F$105 -> 0.0045402951 | H14: =SUM(H13,G14) -> 0.020431328 | I14: =SUM(R14,W14,Z14,AC14) -> #REF! | J14: =SUM(I14,J13) -> #REF! | K14: =J14/$J$104 -> #REF! | L14: =SUM(U14,X14,AA14,AD14) -> #REF! | M14: =SUM(L14,M13) -> #REF! | N14: =G14*AE14 -> 0.0045402951 | O14: =SUM(N14,O13) -> 0.019296254 | P14: =M14/$M$93 -> #REF! | Q14: =R14/F14 -> 0.25 | R14: 1 | S14: L | T14: =IF(S14="L",0.68,IF(S14="JP",0.57,IF(S14="JI",0.57,IF(S14="JD",0.57,IF(S14="P",0.24,IF(S14="I",0.12,IF(S14="D",0.13))))))) -> 0.68 | U14: =T14*R14 -> 0.68 | V14: =W14/F14 -> #REF! | W14: ='CD R Documentación'!O15+'CD R Documentación'!T15+'CD R Documentación'!Y15+'CD R Documentación'!AD15+'CD R Documentación'!AI15+'CD R Documentación'!AN15+#REF! -> #REF! | X14: ='CD R Documentación'!R15+'CD R Documentación'!W15+'CD R Documentación'!AB15+'CD R Documentación'!AG15+'CD R Documentación'!AL15+'CD R Documentación'!AQ15+#REF! -> #REF! | Y14: =Z14/F14 -> 0.75 | Z14: ='CD R Investigación'!P15+'CD R Investigación'!U15+'CD R Investigación'!Z15+'CD R Investigación'!AE15+'CD R Investigación'!AJ15+'CD R Investigación'!AO15+'CD R Investigación'!AT15+'CD R Investigación'!AY15 -> 3 | AA14: ='CD R Investigación'!S15+'CD R Investigación'!X15+'CD R Investigación'!AC15+'CD R Investigación'!AH15+'CD R Investigación'!AM15+'CD R Investigación'!AR15+'CD R Investigación'!AW15+'CD R Investigación'!BB15 -> 1.32 | AB14: =AC14/F14 -> #REF! | AC14: ='CD R Desarrollo'!P15+'CD R Desarrollo'!U15+'CD R Desarrollo'!Z15+'CD R Desarrollo'!AE15+'CD R Desarrollo'!AJ15+'CD R Desarrollo'!AO15+#REF!+#REF! -> #REF! | AD14: ='CD R Desarrollo'!S15+'CD R Desarrollo'!X15+'CD R Desarrollo'!AC15+'CD R Desarrollo'!AH15+'CD R Desarrollo'!AM15+'CD R Desarrollo'!AR15+#REF!+#REF! -> #REF! | AE14: 1 | AF14: ='PL Cronograma detallado'!L64*AE14 -> 7.65 | AG14: =AF14/'PL Cronograma detallado'!M$257 -> #DIV/0! | AH14: =AG14+AH13 -> #DIV/0!
A15: 1.2.8 | B15: Definir Costos | C15: 44658 | D15: 44659 | E15: 1 | F15: 1 | G15: =F15/F$105 -> 0.0011350738 | H15: =SUM(H14,G15) -> 0.021566402 | I15: =SUM(R15,W15,Z15,AC15) -> #REF! | J15: =SUM(I15,J14) -> #REF! | K15: =J15/$J$104 -> #REF! | L15: =SUM(U15,X15,AA15,AD15) -> #REF! | M15: =SUM(L15,M14) -> #REF! | N15: =G15*AE15 -> 0.0011350738 | O15: =SUM(N15,O14) -> 0.020431328 | P15: =M15/$M$93 -> #REF! | Q15: =R15/F15 -> 1 | R15: 1 | S15: L | T15: =IF(S15="L",0.68,IF(S15="JP",0.57,IF(S15="JI",0.57,IF(S15="JD",0.57,IF(S15="P",0.24,IF(S15="I",0.12,IF(S15="D",0.13))))))) -> 0.68 | U15: =T15*R15 -> 0.68 | V15: =W15/F15 -> #REF! | W15: ='CD R Documentación'!O16+'CD R Documentación'!T16+'CD R Documentación'!Y16+'CD R Documentación'!AD16+'CD R Documentación'!AI16+'CD R Documentación'!AN16+#REF! -> #REF! | X15: ='CD R Documentación'!R16+'CD R Documentación'!W16+'CD R Documentación'!AB16+'CD R Documentación'!AG16+'CD R Documentación'!AL16+'CD R Documentación'!AQ16+#REF! -> #REF! | Y15: =Z15/F15 -> 2 | Z15: ='CD R Investigación'!P16+'CD R Investigación'!U16+'CD R Investigación'!Z16+'CD R Investigación'!AE16+'CD R Investigación'!AJ16+'CD R Investigación'!AO16+'CD R Investigación'!AT16+'CD R Investigación'!AY16 -> 2 | AA15: ='CD R Investigación'!S16+'CD R Investigación'!X16+'CD R Investigación'!AC16+'CD R Investigación'!AH16+'CD R Investigación'!AM16+'CD R Investigación'!AR16+'CD R Investigación'!AW16+'CD R Investigación'!BB16 -> 0.88 | AB15: =AC15/F15 -> #REF! | AC15: ='CD R Desarrollo'!P16+'CD R Desarrollo'!U16+'CD R Desarrollo'!Z16+'CD R Desarrollo'!AE16+'CD R Desarrollo'!AJ16+'CD R Desarrollo'!AO16+#REF!+#REF! -> #REF! | AD15: ='CD R Desarrollo'!S16+'CD R Desarrollo'!X16+'CD R Desarrollo'!AC16+'CD R Desarrollo'!AH16+'CD R Desarrollo'!AM16+'CD R Desarrollo'!AR16+#REF!+#REF! -> #REF! | AE15: 1 | AF15: ='PL Cronograma detallado'!L65*AE15 -> 4.37 | AG15: =AF15/'PL Cronograma detallado'!M$257 -> #DIV/0! | AH15: =AG15+AH14 -> #DIV/0!
A16: 1.2.9 | B16: Definir Criterio de Evaluación de Integrantes | C16: 44659 | D16: 44659 | E16: =_xludf.DAYs(D16,C16)+1 -> #NAME? | F16: 1 | G16: =F16/F$105 -> 0.0011350738 | H16: =SUM(H15,G16) -> 0.022701476 | I16: =SUM(R16,W16,Z16,AC16) -> #REF! | J16: =SUM(I16,J15) -> #REF! | K16: =J16/$J$104 -> #REF! | L16: =SUM(U16,X16,AA16,AD16) -> #REF! | M16: =SUM(L16,M15) -> #REF! | N16: =G16*AE16 -> 0.0011350738 | O16: =SUM(N16,O15) -> 0.021566402 | P16: =M16/$M$93 -> #REF! | Q16: =R16/F16 -> 1 | R16: 1 | S16: L | T16: =IF(S16="L",0.68,IF(S16="JP",0.57,IF(S16="JI",0.57,IF(S16="JD",0.57,IF(S16="P",0.24,IF(S16="I",0.12,IF(S16="D",0.13))))))) -> 0.68 | U16: =T16*R16 -> 0.68 | V16: =W16/F16 -> #REF! | W16: ='CD R Documentación'!O17+'CD R Documentación'!T17+'CD R Documentación'!Y17+'CD R Documentación'!AD17+'CD R Documentación'!AI17+'CD R Documentación'!AN17+#REF! -> #REF! | X16: ='CD R Documentación'!R17+'CD R Documentación'!W17+'CD R Documentación'!AB17+'CD R Documentación'!AG17+'CD R Documentación'!AL17+'CD R Documentación'!AQ17+#REF! -> #REF! | Y16: =Z16/F16 -> 2 | Z16: ='CD R Investigación'!P17+'CD R Investigación'!U17+'CD R Investigación'!Z17+'CD R Investigación'!AE17+'CD R Investigación'!AJ17+'CD R Investigación'!AO17+'CD R Investigación'!AT17+'CD R Investigación'!AY17 -> 2 | AA16: ='CD R Investigación'!S17+'CD R Investigación'!X17+'CD R Investigación'!AC17+'CD R Investigación'!AH17+'CD R Investigación'!AM17+'CD R Investigación'!AR17+'CD R Investigación'!AW17+'CD R Investigación'!BB17 -> 0.88 | AB16: =AC16/F16 -> #REF! | AC16: ='CD R Desarrollo'!P17+'CD R Desarrollo'!U17+'CD R Desarrollo'!Z17+'CD R Desarrollo'!AE17+'CD R Desarrollo'!AJ17+'CD R Desarrollo'!AO17+#REF!+#REF! -> #REF! | AD16: ='CD R Desarrollo'!S17+'CD R Desarrollo'!X17+'CD R Desarrollo'!AC17+'CD R Desarrollo'!AH17+'CD R Desarrollo'!AM17+'CD R Desarrollo'!AR17+#REF!+#REF! -> #REF! | AE16: 1 | AF16: ='PL Cronograma detallado'!L29*AE16 -> 0 | AG16: =AF16/'PL Cronograma detallado'!M$257 -> #DIV/0! | AH16: =AG16+AH15 -> #DIV/0!
A17: 1.3 | B17: Elaboración Informe Propuesta | C17: 44656 | D17: 44661 | E17: =_xludf.DAYs(D17,C17)+1 -> #NAME? | F17: 4 | G17: =F17/F$105 -> 0.0045402951 | H17: =SUM(H16,G17) -> 0.027241771 | I17: =SUM(R17,W17,Z17,AC17) -> #REF! | J17: =SUM(I17,J16) -> #REF! | K17: =J17/$J$104 -> #REF! | L17: =SUM(U17,X17,AA17,AD17) -> #REF! | M17: =SUM(L17,M16) -> #REF! | N17: =G17*AE17 -> 0.0045402951 | O17: =SUM(N17,O16) -> 0.026106697 | P17: =M17/$M$93 -> #REF! | Q17: =R17/F17 -> 0.375 | R17: 1.5 | S17: L | T17: =IF(S17="L",0.68,IF(S17="JP",0.57,IF(S17="JI",0.57,IF(S17="JD",0.57,IF(S17="P",0.24,IF(S17="I",0.12,IF(S17="D",0.13))))))) -> 0.68 | U17: =T17*R17 -> 1.02 | V17: =W17/F17 -> #REF! | W17: ='CD R Documentación'!O18+'CD R Documentación'!T18+'CD R Documentación'!Y18+'CD R Documentación'!AD18+'CD R Documentación'!AI18+'CD R Documentación'!AN18+#REF! -> #REF! | X17: ='CD R Documentación'!R18+'CD R Documentación'!W18+'CD R Documentación'!AB18+'CD R Documentación'!AG18+'CD R Documentación'!AL18+'CD R Documentación'!AQ18+#REF! -> #REF! | Y17: =Z17/F17 -> 1 | Z17: ='CD R Investigación'!P18+'CD R Investigación'!U18+'CD R Investigación'!Z18+'CD R Investigación'!AE18+'CD R Investigación'!AJ18+'CD R Investigación'!AO18+'CD R Investigación'!AT18+'CD R Investigación'!AY18 -> 4 | AA17: ='CD R Investigación'!S18+'CD R Investigación'!X18+'CD R Investigación'!AC18+'CD R Investigación'!AH18+'CD R Investigación'!AM18+'CD R Investigación'!AR18+'CD R Investigación'!AW18+'CD R Investigación'!BB18 -> 1.76 | AB17: =AC17/F17 -> #REF! | AC17: ='CD R Desarrollo'!P18+'CD R Desarrollo'!U18+'CD R Desarrollo'!Z18+'CD R Desarrollo'!AE18+'CD R Desarrollo'!AJ18+'CD R Desarrollo'!AO18+#REF!+#REF! -> #REF! | AD17: ='CD R Desarrollo'!S18+'CD R Desarrollo'!X18+'CD R Desarrollo'!AC18+'CD R Desarrollo'!AH18+'CD R Desarrollo'!AM18+'CD R Desarrollo'!AR18+#REF!+#REF! -> #REF! | AE17: 1 | AF17: =#REF!*AE17 -> #REF! | AG17: =AF17/'PL Cronograma detallado'!M$257 -> #REF! | AH17: =AG17+AH16 -> #REF!
A18: 1.3.1 | B18: Reunión de Líderes 1 | C18: 44659 | D18: 44659 | E18: =_xludf.DAYs(D18,C18)+1 -> #NAME? | F18: 1 | G18: =F18/F$105 -> 0.0011350738 | H18: =SUM(H17,G18) -> 0.028376844 | I18: =SUM(R18,W18,Z18,AC18) -> #REF! | J18: =SUM(I18,J17) -> #REF! | K18: =J18/$J$104 -> #REF! | L18: =SUM(U18,X18,AA18,AD18) -> #REF! | M18: =SUM(L18,M17) -> #REF! | N18: =G18*AE18 -> 0.0011350738 | O18: =SUM(N18,O17) -> 0.027241771 | P18: =M18/$M$93 -> #REF! | Q18: =R18/F18 -> 1 | R18: 1 | S18: L | T18: =IF(S18="L",0.68,IF(S18="JP",0.57,IF(S18="JI",0.57,IF(S18="JD",0.57,IF(S18="P",0.24,IF(S18="I",0.12,IF(S18="D",0.13))))))) -> 0.68 | U18: =T18*R18 -> 0.68 | V18: =W18/F18 -> #REF! | W18: ='CD R Documentación'!O19+'CD R Documentación'!T19+'CD R Documentación'!Y19+'CD R Documentación'!AD19+'CD R Documentación'!AI19+'CD R Documentación'!AN19+#REF! -> #REF! | X18: ='CD R Documentación'!R19+'CD R Documentación'!W19+'CD R Documentación'!AB19+'CD R Documentación'!AG19+'CD R Documentación'!AL19+'CD R Documentación'!AQ19+#REF! -> #REF! | Y18: =Z18/F18 -> 2 | Z18: ='CD R Investigación'!P19+'CD R Investigación'!U19+'CD R Investigación'!Z19+'CD R Investigación'!AE19+'CD R Investigación'!AJ19+'CD R Investigación'!AO19+'CD R Investigación'!AT19+'CD R Investigación'!AY19 -> 2 | AA18: ='CD R Investigación'!S19+'CD R Investigación'!X19+'CD R Investigación'!AC19+'CD R Investigación'!AH19+'CD R Investigación'!AM19+'CD R Investigación'!AR19+'CD R Investigación'!AW19+'CD R Investigación'!BB19 -> 0.88 | AB18: =AC18/F18 -> #REF! | AC18: ='CD R Desarrollo'!P19+'CD R Desarrollo'!U19+'CD R Desarrollo'!Z19+'CD R Desarrollo'!AE19+'CD R Desarrollo'!AJ19+'CD R Desarrollo'!AO19+#REF!+#REF! -> #REF! | AD18: ='CD R Desarrollo'!S19+'CD R Desarrollo'!X19+'CD R Desarrollo'!AC19+'CD R Desarrollo'!AH19+'CD R Desarrollo'!AM19+'CD R Desarrollo'!AR19+#REF!+#REF! -> #REF! | AE18: 1 | AF18: ='PL Cronograma detallado'!L66*AE18 -> 21.7 | AG18: =AF18/'PL Cronograma detallado'!M$257 -> #DIV/0! | AH18: =AG18+AH17 -> #DIV/0!
A19: 1.4 | B19: Entrega de Informe de Propuesta v1 | C19: 44662 | D19: 44662 | E19: =_xludf.DAYs(D19,C19)+1 -> #NAME? | F19: 1 | G19: =F19/F$105 -> 0.0011350738 | H19: =SUM(H18,G19) -> 0.029511918 | I19: =SUM(R19,W19,Z19,AC19) -> #REF! | J19: =SUM(I19,J18) -> #REF! | K19: =J19/$J$104 -> #REF! | L19: =SUM(U19,X19,AA19,AD19) -> #REF! | M19: =SUM(L19,M18) -> #REF! | N19: =G19*AE19 -> 0.0011350738 | O19: =SUM(N19,O18) -> 0.028376844 | P19: =M19/$M$93 -> #REF! | Q19: =R19/F19 -> 1 | R19: 1 | S19: L | T19: =IF(S19="L",0.68,IF(S19="JP",0.57,IF(S19="JI",0.57,IF(S19="JD",0.57,IF(S19="P",0.24,IF(S19="I",0.12,IF(S19="D",0.13))))))) -> 0.68 | U19: =T19*R19 -> 0.68 | V19: =W19/F19 -> #REF! | W19: ='CD R Documentación'!O20+'CD R Documentación'!T20+'CD R Documentación'!Y20+'CD R Documentación'!AD20+'CD R Documentación'!AI20+'CD R Documentación'!AN20+#REF! -> #REF! | X19: ='CD R Documentación'!R20+'CD R Documentación'!W20+'CD R Documentación'!AB20+'CD R Documentación'!AG20+'CD R Documentación'!AL20+'CD R Documentación'!AQ20+#REF! -> #REF! | Y19: =Z19/F19 -> 4 | Z19: ='CD R Investigación'!P20+'CD R Investigación'!U20+'CD R Investigación'!Z20+'CD R Investigación'!AE20+'CD R Investigación'!AJ20+'CD R Investigación'!AO20+'CD R Investigación'!AT20+'CD R Investigación'!AY20 -> 4 | AA19: ='CD R Investigación'!S20+'CD R Investigación'!X20+'CD R Investigación'!AC20+'CD R Investigación'!AH20+'CD R Investigación'!AM20+'CD R Investigación'!AR20+'CD R Investigación'!AW20+'CD R Investigación'!BB20 -> 1.76 | AB19: =AC19/F19 -> #REF! | AC19: ='CD R Desarrollo'!P20+'CD R Desarrollo'!U20+'CD R Desarrollo'!Z20+'CD R Desarrollo'!AE20+'CD R Desarrollo'!AJ20+'CD R Desarrollo'!AO20+#REF!+#REF! -> #REF! | AD19: ='CD R Desarrollo'!S20+'CD R Desarrollo'!X20+'CD R Desarrollo'!AC20+'CD R Desarrollo'!AH20+'CD R Desarrollo'!AM20+'CD R Desarrollo'!AR20+#REF!+#REF! -> #REF! | AE19: 1 | AF19: ='PL Cronograma detallado'!L67*AE19 -> 3.57 | AG19: =AF19/'PL Cronograma detallado'!M$257 -> #DIV/0! | AH19: =AG19+AH18 -> #DIV/0!
A20: 2 | B20: Fase de Investigación | C20: 44656 | D20: 44695 | E20: =_xludf.DAYs(D20,C20)+1 -> #NAME? | F20: =SUM(F21,F26,F37) -> 253 | G20: =SUM(G21,G26,G37) -> 0.28717367 | I20: =SUM(I21,I26,I37) -> #REF! | J20: =SUM(I20,J4) -> #REF! | K20: =J20/$J$104 -> #REF! | L20: =SUM(L21,L26,L37) -> #REF! | M20: =SUM(L20,M4) -> #REF! | P20: =M20/$M$93 -> #REF! | Q20: =R20/F20 -> 0 | U20: =T20*R20 -> 0 | X20: ='CD R Documentación'!R21+'CD R Documentación'!W21+'CD R Documentación'!AB21+'CD R Documentación'!AG21+'CD R Documentación'!AL21+'CD R Documentación'!AQ21+#REF! -> #REF! | Z20: ='CD R Investigación'!P21+'CD R Investigación'!U21+'CD R Investigación'!Z21+'CD R Investigación'!AE21+'CD R Investigación'!AJ21+'CD R Investigación'!AO21+'CD R Investigación'!AT21+'CD R Investigación'!AY21 -> 0 | AA20: ='CD R Investigación'!S21+'CD R Investigación'!X21+'CD R Investigación'!AC21+'CD R Investigación'!AH21+'CD R Investigación'!AM21+'CD R Investigación'!AR21+'CD R Investigación'!AW21+'CD R Investigación'!BB21 -> 0 | AC20: ='CD R Desarrollo'!P21+'CD R Desarrollo'!U21+'CD R Desarrollo'!Z21+'CD R Desarrollo'!AE21+'CD R Desarrollo'!AJ21+'CD R Desarrollo'!AO21+#REF!+#REF! -> #REF! | AD20: ='CD R Desarrollo'!S21+'CD R Desarrollo'!X21+'CD R Desarrollo'!AC21+'CD R Desarrollo'!AH21+'CD R Desarrollo'!AM21+'CD R Desarrollo'!AR21+#REF!+#REF! -> #REF!
A21: 2.1 | B21: Relevación de Información de Proyecto GPI 2021-II | C21: 44656 | D21: 44667 | E21: =_xludf.DAYs(D21,C21)+1 -> #NAME? | F21: =SUM(F22:F25) -> 11 | G21: =SUM(G22:G25) -> 0.012485812 | H21: =SUM(G21,H19) -> 0.04199773 | I21: =SUM(I22:I25) -> #REF! | J21: =SUM(I21,J7) -> #REF! | K21: =J21/$J$104 -> #REF! | L21: =SUM(L22:L25) -> #REF! | M21: =SUM(L21,M7) -> #REF! | P21: =M21/$M$93 -> #REF! | X21: ='CD R Documentación'!R22+'CD R Documentación'!W22+'CD R Documentación'!AB22+'CD R Documentación'!AG22+'CD R Documentación'!AL22+'CD R Documentación'!AQ22+#REF! -> #REF! | Z21: ='CD R Investigación'!P22+'CD R Investigación'!U22+'CD R Investigación'!Z22+'CD R Investigación'!AE22+'CD R Investigación'!AJ22+'CD R Investigación'!AO22+'CD R Investigación'!AT22+'CD R Investigación'!AY22 -> 0 | AA21: ='CD R Investigación'!S22+'CD R Investigación'!X22+'CD R Investigación'!AC22+'CD R Investigación'!AH22+'CD R Investigación'!AM22+'CD R Investigación'!AR22+'CD R Investigación'!AW22+'CD R Investigación'!BB22 -> 0 | AC21: ='CD R Desarrollo'!P22+'CD R Desarrollo'!U22+'CD R Desarrollo'!Z22+'CD R Desarrollo'!AE22+'CD R Desarrollo'!AJ22+'CD R Desarrollo'!AO22+#REF!+#REF! -> #REF! | AD21: ='CD R Desarrollo'!S22+'CD R Desarrollo'!X22+'CD R Desarrollo'!AC22+'CD R Desarrollo'!AH22+'CD R Desarrollo'!AM22+'CD R Desarrollo'!AR22+#REF!+#REF! -> #REF!
A22: 2.1.1 | B22: Recolección Documentación Proyecto GPI 2021-II | C22: 44657 | D22: 44657 | E22: =_xludf.DAYs(D22,C22)+1 -> #NAME? | F22: 1 | G22: =F22/F$105 -> 0.0011350738 | H22: =SUM(H19,G22) -> 0.030646992 | I22: =SUM(R22,W22,Z22,AC22) -> #REF! | J22: =SUM(I22,J19) -> #REF! | K22: =J22/$J$104 -> #REF! | L22: =SUM(U22,X22,AA22,AD22) -> #REF! | M22: =SUM(L22,M19) -> #REF! | N22: =G22*AE22 -> 0.0011350738 | O22: =SUM(N22,O19) -> 0.029511918 | P22: =M22/$M$93 -> #REF! | Q22: =R22/F22 -> 0.5 | R22: 0.5 | S22: L | T22: =IF(S22="L",0.68,IF(S22="JP",0.57,IF(S22="JI",0.57,IF(S22="JD",0.57,IF(S22="P",0.24,IF(S22="I",0.12,IF(S22="D",0.13))))))) -> 0.68 | U22: =T22*R22 -> 0.34 | V22: =W22/F22 -> #REF! | W22: ='CD R Documentación'!O23+'CD R Documentación'!T23+'CD R Documentación'!Y23+'CD R Documentación'!AD23+'CD R Documentación'!AI23+'CD R Documentación'!AN23+#REF! -> #REF! | X22: ='CD R Documentación'!R23+'CD R Documentación'!W23+'CD R Documentación'!AB23+'CD R Documentación'!AG23+'CD R Documentación'!AL23+'CD R Documentación'!AQ23+#REF! -> #REF! | Y22: =Z22/F22 -> 0 | Z22: ='CD R Investigación'!P23+'CD R Investigación'!U23+'CD R Investigación'!Z23+'CD R Investigación'!AE23+'CD R Investigación'!AJ23+'CD R Investigación'!AO23+'CD R Investigación'!AT23+'CD R Investigación'!AY23 -> 0 | AA22: ='CD R Investigación'!S23+'CD R Investigación'!X23+'CD R Investigación'!AC23+'CD R Investigación'!AH23+'CD R Investigación'!AM23+'CD R Investigación'!AR23+'CD R Investigación'!AW23+'CD R Investigación'!BB23 -> 0 | AB22: =AC22/F22 -> #REF! | AC22: ='CD R Desarrollo'!P23+'CD R Desarrollo'!U23+'CD R Desarrollo'!Z23+'CD R Desarrollo'!AE23+'CD R Desarrollo'!AJ23+'CD R Desarrollo'!AO23+#REF!+#REF! -> #REF! | AD22: ='CD R Desarrollo'!S23+'CD R Desarrollo'!X23+'CD R Desarrollo'!AC23+'CD R Desarrollo'!AH23+'CD R Desarrollo'!AM23+'CD R Desarrollo'!AR23+#REF!+#REF! -> #REF! | AE22: 1 | AF22: ='PL Cronograma detallado'!L70*AE22 -> 8.85 | AG22: =AF22/'PL Cronograma detallado'!M$257 -> #DIV/0! | AH22: =AG22+AH19 -> #DIV/0!
A23: 2.1.2 | B23: Obtención Repositorio Proyecto GPI 2021-II | C23: 44657 | D23: 44657 | E23: =_xludf.DAYs(D23,C23)+1 -> #NAME? | F23: 1 | G23: =F23/F$105 -> 0.0011350738 | H23: =SUM(H22,G23) -> 0.031782066 | I23: =SUM(R23,W23,Z23,AC23) -> #REF! | J23: =SUM(I23,J22) -> #REF! | K23: =J23/$J$104 -> #REF! | L23: =SUM(U23,X23,AA23,AD23) -> #REF! | M23: =SUM(L23,M22) -> #REF! | N23: =G23*AE23 -> 0.0011350738 | O23: =SUM(N23,O22) -> 0.030646992 | P23: =M23/$M$93 -> #REF! | Q23: =R23/F23 -> 1 | R23: 1 | S23: L | T23: =IF(S23="L",0.68,IF(S23="JP",0.57,IF(S23="JI",0.57,IF(S23="JD",0.57,IF(S23="P",0.24,IF(S23="I",0.12,IF(S23="D",0.13))))))) -> 0.68 | U23: =T23*R23 -> 0.68 | V23: =W23/F23 -> #REF! | W23: ='CD R Documentación'!O24+'CD R Documentación'!T24+'CD R Documentación'!Y24+'CD R Documentación'!AD24+'CD R Documentación'!AI24+'CD R Documentación'!AN24+#REF! -> #REF! | X23: ='CD R Documentación'!R24+'CD R Documentación'!W24+'CD R Documentación'!AB24+'CD R Documentación'!AG24+'CD R Documentación'!AL24+'CD R Documentación'!AQ24+#REF! -> #REF! | Y23: =Z23/F23 -> 0 | Z23: ='CD R Investigación'!P24+'CD R Investigación'!U24+'CD R Investigación'!Z24+'CD R Investigación'!AE24+'CD R Investigación'!AJ24+'CD R Investigación'!AO24+'CD R Investigación'!AT24+'CD R Investigación'!AY24 -> 0 | AA23: ='CD R Investigación'!S24+'CD R Investigación'!X24+'CD R Investigación'!AC24+'CD R Investigación'!AH24+'CD R Investigación'!AM24+'CD R Investigación'!AR24+'CD R Investigación'!AW24+'CD R Investigación'!BB24 -> 0 | AB23: =AC23/F23 -> #REF! | AC23: ='CD R Desarrollo'!P24+'CD R Desarrollo'!U24+'CD R Desarrollo'!Z24+'CD R Desarrollo'!AE24+'CD R Desarrollo'!AJ24+'CD R Desarrollo'!AO24+#REF!+#REF! -> #REF! | AD23: ='CD R Desarrollo'!S24+'CD R Desarrollo'!X24+'CD R Desarrollo'!AC24+'CD R Desarrollo'!AH24+'CD R Desarrollo'!AM24+'CD R Desarrollo'!AR24+#REF!+#REF! -> #REF! | AE23: 1 | AF23: ='PL Cronograma detallado'!L71*AE23 -> 3.43 | AG23: =AF23/'PL Cronograma detallado'!M$257 -> #DIV/0! | AH23: =AG23+AH22 -> #DIV/0!
A24: 2.1.3 | B24: Análisis de Documentación de Proyecto GPI 2021-II | C24: 44658 | D24: 44667 | E24: =_xludf.DAYs(D24,C24)+1 -> #NAME? | F24: 8 | G24: =F24/F$105 -> 0.0090805902 | H24: =SUM(H23,G24) -> 0.040862656 | I24: =SUM(R24,W24,Z24,AC24) -> #REF! | J24: =SUM(I24,J23) -> #REF! | K24: =J24/$J$104 -> #REF! | L24: =SUM(U24,X24,AA24,AD24) -> #REF! | M24: =SUM(L24,M23) -> #REF! | N24: =G24*AE24 -> 0.0090805902 | O24: =SUM(N24,O23) -> 0.039727582 | P24: =M24/$M$93 -> #REF! | Q24: =R24/F24 -> 0.0625 | R24: 0.5 | S24: L | T24: =IF(S24="L",0.68,IF(S24="JP",0.57,IF(S24="JI",0.57,IF(S24="JD",0.57,IF(S24="P",0.24,IF(S24="I",0.12,IF(S24="D",0.13))))))) -> 0.68 | U24: =T24*R24 -> 0.34 | V24: =W24/F24 -> #REF! | W24: ='CD R Documentación'!O25+'CD R Documentación'!T25+'CD R Documentación'!Y25+'CD R Documentación'!AD25+'CD R Documentación'!AI25+'CD R Documentación'!AN25+#REF! -> #REF! | X24: ='CD R Documentación'!R25+'CD R Documentación'!W25+'CD R Documentación'!AB25+'CD R Documentación'!AG25+'CD R Documentación'!AL25+'CD R Documentación'!AQ25+#REF! -> #REF! | Y24: =Z24/F24 -> 1 | Z24: ='CD R Investigación'!P25+'CD R Investigación'!U25+'CD R Investigación'!Z25+'CD R Investigación'!AE25+'CD R Investigación'!AJ25+'CD R Investigación'!AO25+'CD R Investigación'!AT25+'CD R Investigación'!AY25 -> 8 | AA24: ='CD R Investigación'!S25+'CD R Investigación'!X25+'CD R Investigación'!AC25+'CD R Investigación'!AH25+'CD R Investigación'!AM25+'CD R Investigación'!AR25+'CD R Investigación'!AW25+'CD R Investigación'!BB25 -> 3.52 | AB24: =AC24/F24 -> #REF! | AC24: ='CD R Desarrollo'!P25+'CD R Desarrollo'!U25+'CD R Desarrollo'!Z25+'CD R Desarrollo'!AE25+'CD R Desarrollo'!AJ25+'CD R Desarrollo'!AO25+#REF!+#REF! -> #REF! | AD24: ='CD R Desarrollo'!S25+'CD R Desarrollo'!X25+'CD R Desarrollo'!AC25+'CD R Desarrollo'!AH25+'CD R Desarrollo'!AM25+'CD R Desarrollo'!AR25+#REF!+#REF! -> #REF! | AE24: 1 | AF24: ='PL Cronograma detallado'!L72*AE24 -> 3.13 | AG24: =AF24/'PL Cronograma detallado'!M$257 -> #DIV/0! | AH24: =AG24+AH23 -> #DIV/0!
A25: 2.1.4 | B25: Reunión de Líderes 2 | C25: 44666 | D25: 44666 | E25: =_xludf.DAYs(D25,C25)+1 -> #NAME? | F25: 1 | G25: =F25/F$105 -> 0.0011350738 | H25: =SUM(H24,G25) -> 0.04199773 | I25: =SUM(R25,W25,Z25,AC25) -> #REF! | J25: =SUM(I25,J24) -> #REF! | K25: =J25/$J$104 -> #REF! | L25: =SUM(U25,X25,AA25,AD25) -> #REF! | M25: =SUM(L25,M24) -> #REF! | N25: =G25*AE25 -> 0.0011350738 | O25: =SUM(N25,O24) -> 0.040862656 | P25: =M25/$M$93 -> #REF! | Q25: =R25/F25 -> 1 | R25: 1 | S25: L | T25: =IF(S25="L",0.68,IF(S25="JP",0.57,IF(S25="JI",0.57,IF(S25="JD",0.57,IF(S25="P",0.24,IF(S25="I",0.12,IF(S25="D",0.13))))))) -> 0.68 | U25: =T25*R25 -> 0.68 | V25: =W25/F25 -> #REF! | W25: ='CD R Documentación'!O26+'CD R Documentación'!T26+'CD R Documentación'!Y26+'CD R Documentación'!AD26+'CD R Documentación'!AI26+'CD R Documentación'!AN26+#REF! -> #REF! | X25: ='CD R Documentación'!R26+'CD R Documentación'!W26+'CD R Documentación'!AB26+'CD R Documentación'!AG26+'CD R Documentación'!AL26+'CD R Documentación'!AQ26+#REF! -> #REF! | Y25: =Z25/F25 -> 0 | Z25: ='CD R Investigación'!P26+'CD R Investigación'!U26+'CD R Investigación'!Z26+'CD R Investigación'!AE26+'CD R Investigación'!AJ26+'CD R Investigación'!AO26+'CD R Investigación'!AT26+'CD R Investigación'!AY26 -> 0 | AA25: ='CD R Investigación'!S26+'CD R Investigación'!X26+'CD R Investigación'!AC26+'CD R Investigación'!AH26+'CD R Investigación'!AM26+'CD R Investigación'!AR26+'CD R Investigación'!AW26+'CD R Investigación'!BB26 -> 0 | AB25: =AC25/F25 -> #REF! | AC25: ='CD R Desarrollo'!P26+'CD R Desarrollo'!U26+'CD R Desarrollo'!Z26+'CD R Desarrollo'!AE26+'CD R Desarrollo'!AJ26+'CD R Desarrollo'!AO26+#REF!+#REF! -> #REF! | AD25: ='CD R Desarrollo'!S26+'CD R Desarrollo'!X26+'CD R Desarrollo'!AC26+'CD R Desarrollo'!AH26+'CD R Desarrollo'!AM26+'CD R Desarrollo'!AR26+#REF!+#REF! -> #REF! | AE25: 1 | AF25: ='PL Cronograma detallado'!L73*AE25 -> 2.29 | AG25: =AF25/'PL Cronograma detallado'!M$257 -> #DIV/0! | AH25: =AG25+AH24 -> #DIV/0!
A26: 2.2 | B26: Investigación Bibliométrica y Altmetric | C26: 44669 | D26: 44688 | E26: =_xludf.DAYs(D26,C26)+1 -> #NAME? | F26: =SUM(F27:F36) -> 62 | G26: =SUM(G27:G36) -> 0.070374574 | H26: =SUM(H25,G26) -> 0.1123723 | I26: =SUM(I27:I36) -> #REF! | J26: =SUM(I26,J21) -> #REF! | K26: =J26/$J$104 -> #REF! | L26: =SUM(L27:L36) -> #REF! | M26: =SUM(L26,M21) -> #REF! | P26: =M26/$M$93 -> #REF! | W26: ='CD R Documentación'!O27+'CD R Documentación'!T27+'CD R Documentación'!Y27+'CD R Documentación'!AD27+'CD R Documentación'!AI27+'CD R Documentación'!AN27+#REF! -> #REF! | X26: ='CD R Documentación'!R27+'CD R Documentación'!W27+'CD R Documentación'!AB27+'CD R Documentación'!AG27+'CD R Documentación'!AL27+'CD R Documentación'!AQ27+#REF! -> #REF! | Z26: ='CD R Investigación'!P27+'CD R Investigación'!U27+'CD R Investigación'!Z27+'CD R Investigación'!AE27+'CD R Investigación'!AJ27+'CD R Investigación'!AO27+'CD R Investigación'!AT27+'CD R Investigación'!AY27 -> 0 | AA26: ='CD R Investigación'!S27+'CD R Investigación'!X27+'CD R Investigación'!AC27+'CD R Investigación'!AH27+'CD R Investigación'!AM27+'CD R Investigación'!AR27+'CD R Investigación'!AW27+'CD R Investigación'!BB27 -> 0 | AC26: ='CD R Desarrollo'!P27+'CD R Desarrollo'!U27+'CD R Desarrollo'!Z27+'CD R Desarrollo'!AE27+'CD R Desarrollo'!AJ27+'CD R Desarrollo'!AO27+#REF!+#REF! -> #REF! | AD26: ='CD R Desarrollo'!S27+'CD R Desarrollo'!X27+'CD R Desarrollo'!AC27+'CD R Desarrollo'!AH27+'CD R Desarrollo'!AM27+'CD R Desarrollo'!AR27+#REF!+#REF! -> #REF!
A27: H1 | B27: Entrega de Informe de Propuesta vf | C27: 44670 | D27: 44670 | E27: =_xludf.DAYs(D27,C27)+1 -> #NAME? | F27: 1 | G27: =(F27/F$105) -> 0.0011350738 | H27: =SUM(H25,G27) -> 0.043132804 | I27: =SUM(R27,W27,Z27,AC27) -> #REF! | J27: =SUM(I27,J25) -> #REF! | K27: =J27/$J$104 -> #REF! | L27: =SUM(U27,X27,AA27,AD27) -> #REF! | M27: =SUM(L27,M25) -> #REF! | N27: =G27*AE27 -> 0.0011350738 | O27: =SUM(N27,O25) -> 0.04199773 | P27: =M27/$M$93 -> #REF! | Q27: =R27/F27 -> 1 | R27: 1 | S27: L | T27: =IF(S27="L",0.68,IF(S27="JP",0.57,IF(S27="JI",0.57,IF(S27="JD",0.57,IF(S27="P",0.24,IF(S27="I",0.12,IF(S27="D",0.13))))))) -> 0.68 | U27: =T27*R27 -> 0.68 | V27: =W27/F27 -> #REF! | W27: ='CD R Documentación'!O28+'CD R Documentación'!T28+'CD R Documentación'!Y28+'CD R Documentación'!AD28+'CD R Documentación'!AI28+'CD R Documentación'!AN28+#REF! -> #REF! | X27: ='CD R Documentación'!R28+'CD R Documentación'!W28+'CD R Documentación'!AB28+'CD R Documentación'!AG28+'CD R Documentación'!AL28+'CD R Documentación'!AQ28+#REF! -> #REF! | Y27: =Z27/F27 -> 0 | Z27: ='CD R Investigación'!P28+'CD R Investigación'!U28+'CD R Investigación'!Z28+'CD R Investigación'!AE28+'CD R Investigación'!AJ28+'CD R Investigación'!AO28+'CD R Investigación'!AT28+'CD R Investigación'!AY28 -> 0 | AA27: ='CD R Investigación'!S28+'CD R Investigación'!X28+'CD R Investigación'!AC28+'CD R Investigación'!AH28+'CD R Investigación'!AM28+'CD R Investigación'!AR28+'CD R Investigación'!AW28+'CD R Investigación'!BB28 -> 0 | AB27: =AC27/F27 -> #REF! | AC27: ='CD R Desarrollo'!P28+'CD R Desarrollo'!U28+'CD R Desarrollo'!Z28+'CD R Desarrollo'!AE28+'CD R Desarrollo'!AJ28+'CD R Desarrollo'!AO28+#REF!+#REF! -> #REF! | AD27: ='CD R Desarrollo'!S28+'CD R Desarrollo'!X28+'CD R Desarrollo'!AC28+'CD R Desarrollo'!AH28+'CD R Desarrollo'!AM28+'CD R Desarrollo'!AR28+#REF!+#REF! -> #REF! | AE27: 1 | AF27: ='PL Cronograma detallado'!L76*AE27 -> 7.73 | AG27: =AF27/'PL Cronograma detallado'!M$257 -> #DIV/0! | AH27: =AG27+AH25 -> #DIV/0!
A28: 2.2.1 | B28: Definición de Instrumentos de Análisis Bibliométricos | C28: 44670 | D28: 44671 | E28: =_xludf.DAYs(D28,C28)+1 -> #NAME? | F28: 2 | G28: =F28/F$105 -> 0.0022701476 | H28: =SUM(H27,G28) -> 0.045402951 | I28: =SUM(R28,W28,Z28,AC28) -> #REF! | J28: =SUM(I28,J27) -> #REF! | K28: =J28/$J$104 -> #REF! | L28: =SUM(U28,X28,AA28,AD28) -> #REF! | M28: =SUM(L28,M27) -> #REF! | N28: =G28*AE28 -> 0.0022701476 | O28: =SUM(N28,O27) -> 0.044267877 | P28: =M28/$M$93 -> #REF! | Q28: =R28/F28 -> 0 | R28: 0 | S28: L | T28: =IF(S28="L",0.68,IF(S28="JP",0.57,IF(S28="JI",0.57,IF(S28="JD",0.57,IF(S28="P",0.24,IF(S28="I",0.12,IF(S28="D",0.13))))))) -> 0.68 | U28: =T28*R28 -> 0 | V28: =W28/F28 -> #REF! | W28: ='CD R Documentación'!O29+'CD R Documentación'!T29+'CD R Documentación'!Y29+'CD R Documentación'!AD29+'CD R Documentación'!AI29+'CD R Documentación'!AN29+#REF! -> #REF! | X28: ='CD R Documentación'!R29+'CD R Documentación'!W29+'CD R Documentación'!AB29+'CD R Documentación'!AG29+'CD R Documentación'!AL29+'CD R Documentación'!AQ29+#REF! -> #REF! | Y28: =Z28/F28 -> 0 | Z28: ='CD R Investigación'!P29+'CD R Investigación'!U29+'CD R Investigación'!Z29+'CD R Investigación'!AE29+'CD R Investigación'!AJ29+'CD R Investigación'!AO29+'CD R Investigación'!AT29+'CD R Investigación'!AY29 -> 0 | AA28: ='CD R Investigación'!S29+'CD R Investigación'!X29+'CD R Investigación'!AC29+'CD R Investigación'!AH29+'CD R Investigación'!AM29+'CD R Investigación'!AR29+'CD R Investigación'!AW29+'CD R Investigación'!BB29 -> 0 | AB28: =AC28/F28 -> #REF! | AC28: ='CD R Desarrollo'!P29+'CD R Desarrollo'!U29+'CD R Desarrollo'!Z29+'CD R Desarrollo'!AE29+'CD R Desarrollo'!AJ29+'CD R Desarrollo'!AO29+#REF!+#REF! -> #REF! | AD28: ='CD R Desarrollo'!S29+'CD R Desarrollo'!X29+'CD R Desarrollo'!AC29+'CD R Desarrollo'!AH29+'CD R Desarrollo'!AM29+'CD R Desarrollo'!AR29+#REF!+#REF! -> #REF! | AE28: 1 | AF28: ='PL Cronograma detallado'!L78*AE28 -> 6.84 | AG28: =AF28/'PL Cronograma detallado'!M$257 -> #DIV/0! | AH28: =AG28+AH27 -> #DIV/0!
A29: 2.2.2 | B29: Definción de Instrumentos de Análisis Altmetric | C29: 44670 | D29: 44671 | E29: =_xludf.DAYs(D29,C29)+1 -> #NAME? | F29: 2 | G29: =F29/F$105 -> 0.0022701476 | H29: =SUM(H28,G29) -> 0.047673099 | I29: =SUM(R29,W29,Z29,AC29) -> #REF! | J29: =SUM(I29,J28) -> #REF! | K29: =J29/$J$104 -> #REF! | L29: =SUM(U29,X29,AA29,AD29) -> #REF! | M29: =SUM(L29,M28) -> #REF! | N29: =G29*AE29 -> 0.0022701476 | O29: =SUM(N29,O28) -> 0.046538025 | P29: =M29/$M$93 -> #REF! | Q29: =R29/F29 -> 0 | R29: 0 | S29: L | T29: =IF(S29="L",0.68,IF(S29="JP",0.57,IF(S29="JI",0.57,IF(S29="JD",0.57,IF(S29="P",0.24,IF(S29="I",0.12,IF(S29="D",0.13))))))) -> 0.68 | U29: =T29*R29 -> 0 | V29: =W29/F29 -> #REF! | W29: ='CD R Documentación'!O30+'CD R Documentación'!T30+'CD R Documentación'!Y30+'CD R Documentación'!AD30+'CD R Documentación'!AI30+'CD R Documentación'!AN30+#REF! -> #REF! | X29: ='CD R Documentación'!R30+'CD R Documentación'!W30+'CD R Documentación'!AB30+'CD R Documentación'!AG30+'CD R Documentación'!AL30+'CD R Documentación'!AQ30+#REF! -> #REF! | Y29: =Z29/F29 -> 0 | Z29: ='CD R Investigación'!P30+'CD R Investigación'!U30+'CD R Investigación'!Z30+'CD R Investigación'!AE30+'CD R Investigación'!AJ30+'CD R Investigación'!AO30+'CD R Investigación'!AT30+'CD R Investigación'!AY30 -> 0 | AA29: ='CD R Investigación'!S30+'CD R Investigación'!X30+'CD R Investigación'!AC30+'CD R Investigación'!AH30+'CD R Investigación'!AM30+'CD R Investigación'!AR30+'CD R Investigación'!AW30+'CD R Investigación'!BB30 -> 0 | AB29: =AC29/F29 -> #REF! | AC29: ='CD R Desarrollo'!P30+'CD R Desarrollo'!U30+'CD R Desarrollo'!Z30+'CD R Desarrollo'!AE30+'CD R Desarrollo'!AJ30+'CD R Desarrollo'!AO30+#REF!+#REF! -> #REF! | AD29: ='CD R Desarrollo'!S30+'CD R Desarrollo'!X30+'CD R Desarrollo'!AC30+'CD R Desarrollo'!AH30+'CD R Desarrollo'!AM30+'CD R Desarrollo'!AR30+#REF!+#REF! -> #REF! | AE29: 1 | AF29: ='PL Cronograma detallado'!L79*AE29 -> 0 | AG29: =AF29/'PL Cronograma detallado'!M$257 -> #DIV/0! | AH29: =AG29+AH28 -> #DIV/0!
A30: 2.2.3 | B30: Analizar Estado del Arte de la Fase Anterior del Proyecto (Parte 1) | C30: 44671 | D30: 44677 | E30: =_xludf.DAYs(D30,C30)+1 -> #NAME? | F30: 14 | G30: =F30/F$105 -> 0.015891033 | H30: =SUM(H29,G30) -> 0.063564132 | I30: =SUM(R30,W30,Z30,AC30) -> #REF! | J30: =SUM(I30,J29) -> #REF! | K30: =J30/$J$104 -> #REF! | L30: =SUM(U30,X30,AA30,AD30) -> #REF! | M30: =SUM(L30,M29) -> #REF! | N30: =G30*AE30 -> 0.015891033 | O30: =SUM(N30,O29) -> 0.062429058 | P30: =M30/$M$93 -> #REF! | Q30: =R30/F30 -> 0 | R30: 0 | S30: L | T30: =IF(S30="L",0.68,IF(S30="JP",0.57,IF(S30="JI",0.57,IF(S30="JD",0.57,IF(S30="P",0.24,IF(S30="I",0.12,IF(S30="D",0.13))))))) -> 0.68 | U30: =T30*R30 -> 0 | V30: =W30/F30 -> #REF! | W30: ='CD R Documentación'!O31+'CD R Documentación'!T31+'CD R Documentación'!Y31+'CD R Documentación'!AD31+'CD R Documentación'!AI31+'CD R Documentación'!AN31+#REF! -> #REF! | X30: ='CD R Documentación'!R31+'CD R Documentación'!W31+'CD R Documentación'!AB31+'CD R Documentación'!AG31+'CD R Documentación'!AL31+'CD R Documentación'!AQ31+#REF! -> #REF! | Y30: =Z30/F30 -> 0 | Z30: ='CD R Investigación'!P31+'CD R Investigación'!U31+'CD R Investigación'!Z31+'CD R Investigación'!AE31+'CD R Investigación'!AJ31+'CD R Investigación'!AO31+'CD R Investigación'!AT31+'CD R Investigación'!AY31 -> 0 | AA30: ='CD R Investigación'!S31+'CD R Investigación'!X31+'CD R Investigación'!AC31+'CD R Investigación'!AH31+'CD R Investigación'!AM31+'CD R Investigación'!AR31+'CD R Investigación'!AW31+'CD R Investigación'!BB31 -> 0 | AB30: =AC30/F30 -> #REF! | AC30: ='CD R Desarrollo'!P31+'CD R Desarrollo'!U31+'CD R Desarrollo'!Z31+'CD R Desarrollo'!AE31+'CD R Desarrollo'!AJ31+'CD R Desarrollo'!AO31+#REF!+#REF! -> #REF! | AD30: ='CD R Desarrollo'!S31+'CD R Desarrollo'!X31+'CD R Desarrollo'!AC31+'CD R Desarrollo'!AH31+'CD R Desarrollo'!AM31+'CD R Desarrollo'!AR31+#REF!+#REF! -> #REF! | AE30: 1 | AF30: ='PL Cronograma detallado'!L80*AE30 -> 162.08 | AG30: =AF30/'PL Cronograma detallado'!M$257 -> #DIV/0! | AH30: =AG30+AH29 -> #DIV/0!
A31: 2.2.4 | B31: Reunión de Líderes 3 | C31: 44673 | D31: 44673 | E31: =_xludf.DAYs(D31,C31)+1 -> #NAME? | F31: 1 | G31: =F31/F$105 -> 0.0011350738 | H31: =SUM(H30,G31) -> 0.064699205 | I31: =SUM(R31,W31,Z31,AC31) -> #REF! | J31: =SUM(I31,J30) -> #REF! | K31: =J31/$J$104 -> #REF! | L31: =SUM(U31,X31,AA31,AD31) -> #REF! | M31: =SUM(L31,M30) -> #REF! | N31: =G31*AE31 -> 0.0011350738 | O31: =SUM(N31,O30) -> 0.063564132 | P31: =M31/$M$93 -> #REF! | Q31: =R31/F31 -> 1 | R31: 1 | S31: L | T31: =IF(S31="L",0.68,IF(S31="JP",0.57,IF(S31="JI",0.57,IF(S31="JD",0.57,IF(S31="P",0.24,IF(S31="I",0.12,IF(S31="D",0.13))))))) -> 0.68 | U31: =T31*R31 -> 0.68 | V31: =W31/F31 -> 1 | W31: 1 | X31: ='CD R Documentación'!R32+'CD R Documentación'!W32+'CD R Documentación'!AB32+'CD R Documentación'!AG32+'CD R Documentación'!AL32+'CD R Documentación'!AQ32+#REF! -> #REF! | Y31: =Z31/F31 -> 1 | Z31: 1 | AA31: ='CD R Investigación'!S32+'CD R Investigación'!X32+'CD R Investigación'!AC32+'CD R Investigación'!AH32+'CD R Investigación'!AM32+'CD R Investigación'!AR32+'CD R Investigación'!AW32+'CD R Investigación'!BB32 -> 2.64 | AB31: =AC31/F31 -> #REF! | AC31: ='CD R Desarrollo'!P32+'CD R Desarrollo'!U32+'CD R Desarrollo'!Z32+'CD R Desarrollo'!AE32+'CD R Desarrollo'!AJ32+'CD R Desarrollo'!AO32+#REF!+#REF! -> #REF! | AD31: ='CD R Desarrollo'!S32+'CD R Desarrollo'!X32+'CD R Desarrollo'!AC32+'CD R Desarrollo'!AH32+'CD R Desarrollo'!AM32+'CD R Desarrollo'!AR32+#REF!+#REF! -> #REF! | AE31: 1 | AF31: ='PL Cronograma detallado'!L127*AE31 -> 10.6 | AG31: =AF31/'PL Cronograma detallado'!M$257 -> #DIV/0! | AH31: =AG31+AH30 -> #DIV/0!
A32: 2.2.5 | B32: Definir Estrategias de Búsqueda | C32: 44674 | D32: 44674 | E32: =_xludf.DAYs(D32,C32)+1 -> #NAME? | F32: 2 | G32: =F32/F$105 -> 0.0022701476 | H32: =SUM(H31,G32) -> 0.066969353 | I32: =SUM(R32,W32,Z32,AC32) -> #REF! | J32: =SUM(I32,J31) -> #REF! | K32: =J32/$J$104 -> #REF! | L32: =SUM(U32,X32,AA32,AD32) -> #REF! | M32: =SUM(L32,M31) -> #REF! | N32: =G32*AE32 -> 0.0022701476 | O32: =SUM(N32,O31) -> 0.065834279 | P32: =M32/$M$93 -> #REF! | Q32: =R32/F32 -> 0 | R32: 0 | S32: L | T32: =IF(S32="L",0.68,IF(S32="JP",0.57,IF(S32="JI",0.57,IF(S32="JD",0.57,IF(S32="P",0.24,IF(S32="I",0.12,IF(S32="D",0.13))))))) -> 0.68 | U32: =T32*R32 -> 0 | V32: =W32/F32 -> #REF! | W32: ='CD R Documentación'!O33+'CD R Documentación'!T33+'CD R Documentación'!Y33+'CD R Documentación'!AD33+'CD R Documentación'!AI33+'CD R Documentación'!AN33+#REF! -> #REF! | X32: ='CD R Documentación'!R33+'CD R Documentación'!W33+'CD R Documentación'!AB33+'CD R Documentación'!AG33+'CD R Documentación'!AL33+'CD R Documentación'!AQ33+#REF! -> #REF! | Y32: =Z32/F32 -> 3 | Z32: ='CD R Investigación'!P33+'CD R Investigación'!U33+'CD R Investigación'!Z33+'CD R Investigación'!AE33+'CD R Investigación'!AJ33+'CD R Investigación'!AO33+'CD R Investigación'!AT33+'CD R Investigación'!AY33 -> 6 | AA32: ='CD R Investigación'!S33+'CD R Investigación'!X33+'CD R Investigación'!AC33+'CD R Investigación'!AH33+'CD R Investigación'!AM33+'CD R Investigación'!AR33+'CD R Investigación'!AW33+'CD R Investigación'!BB33 -> 2.64 | AB32: =AC32/F32 -> #REF! | AC32: ='CD R Desarrollo'!P33+'CD R Desarrollo'!U33+'CD R Desarrollo'!Z33+'CD R Desarrollo'!AE33+'CD R Desarrollo'!AJ33+'CD R Desarrollo'!AO33+#REF!+#REF! -> #REF! | AD32: ='CD R Desarrollo'!S33+'CD R Desarrollo'!X33+'CD R Desarrollo'!AC33+'CD R Desarrollo'!AH33+'CD R Desarrollo'!AM33+'CD R Desarrollo'!AR33+#REF!+#REF! -> #REF! | AE32: 1 | AF32: ='PL Cronograma detallado'!L128*AE32 -> 4.54 | AG32: =AF32/'PL Cronograma detallado'!M$257 -> #DIV/0! | AH32: =AG32+AH31 -> #DIV/0!
A33: 2.2.6 | B33: Realizar análisis bibliométrico en Springer Link y Virtual Pro | C33: 44676 | D33: 44688 | E33: =_xludf.DAYs(D33,C33)+1 -> #NAME? | F33: 10 | G33: =F33/F$105 -> 0.011350738 | H33: =SUM(H32,G33) -> 0.078320091 | I33: =SUM(R33,W33,Z33,AC33) -> #REF! | J33: =SUM(I33,J32) -> #REF! | K33: =J33/$J$104 -> #REF! | L33: =SUM(U33,X33,AA33,AD33) -> #REF! | M33: =SUM(L33,M32) -> #REF! | N33: =G33*AE33 -> 0.011350738 | O33: =SUM(N33,O32) -> 0.077185017 | P33: =M33/$M$93 -> #REF! | Q33: =R33/F33 -> 0 | R33: 0 | S33: L | T33: =IF(S33="L",0.68,IF(S33="JP",0.57,IF(S33="JI",0.57,IF(S33="JD",0.57,IF(S33="P",0.24,IF(S33="I",0.12,IF(S33="D",0.13))))))) -> 0.68 | U33: =T33*R33 -> 0 | V33: =W33/F33 -> #REF! | W33: ='CD R Documentación'!O34+'CD R Documentación'!T34+'CD R Documentación'!Y34+'CD R Documentación'!AD34+'CD R Documentación'!AI34+'CD R Documentación'!AN34+#REF! -> #REF! | X33: ='CD R Documentación'!R34+'CD R Documentación'!W34+'CD R Documentación'!AB34+'CD R Documentación'!AG34+'CD R Documentación'!AL34+'CD R Documentación'!AQ34+#REF! -> #REF! | Y33: =Z33/F33 -> 0.6 | Z33: ='CD R Investigación'!P34+'CD R Investigación'!U34+'CD R Investigación'!Z34+'CD R Investigación'!AE34+'CD R Investigación'!AJ34+'CD R Investigación'!AO34+'CD R Investigación'!AT34+'CD R Investigación'!AY34 -> 6 | AA33: ='CD R Investigación'!S34+'CD R Investigación'!X34+'CD R Investigación'!AC34+'CD R Investigación'!AH34+'CD R Investigación'!AM34+'CD R Investigación'!AR34+'CD R Investigación'!AW34+'CD R Investigación'!BB34 -> 2.64 | AB33: =AC33/F33 -> #REF! | AC33: ='CD R Desarrollo'!P34+'CD R Desarrollo'!U34+'CD R Desarrollo'!Z34+'CD R Desarrollo'!AE34+'CD R Desarrollo'!AJ34+'CD R Desarrollo'!AO34+#REF!+#REF! -> #REF! | AD33: ='CD R Desarrollo'!S34+'CD R Desarrollo'!X34+'CD R Desarrollo'!AC34+'CD R Desarrollo'!AH34+'CD R Desarrollo'!AM34+'CD R Desarrollo'!AR34+#REF!+#REF! -> #REF! | AE33: 1 | AF33: ='PL Cronograma detallado'!L129*AE33 -> 4.54 | AG33: =AF33/'PL Cronograma detallado'!M$257 -> #DIV/0! | AH33: =AG33+AH32 -> #DIV/0!
A34: 2.2.7 | B34: Realizar análisis bibliométrico en Proquest Engineering, Proquest D&T y Science Direct | C34: 44676 | D34: 44695 | E34: =_xludf.DAYs(D34,C34)+1 -> #NAME? | F34: 10 | G34: =F34/F$105 -> 0.011350738 | H34: =SUM(H33,G34) -> 0.089670829 | I34: =SUM(R34,W34,Z34,AC34) -> #REF! | J34: =SUM(I34,J33) -> #REF! | K34: =J34/$J$104 -> #REF! | L34: =SUM(U34,X34,AA34,AD34) -> #REF! | M34: =SUM(L34,M33) -> #REF! | N34: =G34*AE34 -> 0.011350738 | O34: =SUM(N34,O33) -> 0.088535755 | P34: =M34/$M$93 -> #REF! | Q34: =R34/F34 -> 0 | R34: 0 | S34: L | T34: =IF(S34="L",0.68,IF(S34="JP",0.57,IF(S34="JI",0.57,IF(S34="JD",0.57,IF(S34="P",0.24,IF(S34="I",0.12,IF(S34="D",0.13))))))) -> 0.68 | U34: =T34*R34 -> 0 | V34: =W34/F34 -> #REF! | W34: ='CD R Documentación'!O35+'CD R Documentación'!T35+'CD R Documentación'!Y35+'CD R Documentación'!AD35+'CD R Documentación'!AI35+'CD R Documentación'!AN35+#REF! -> #REF! | X34: ='CD R Documentación'!R35+'CD R Documentación'!W35+'CD R Documentación'!AB35+'CD R Documentación'!AG35+'CD R Documentación'!AL35+'CD R Documentación'!AQ35+#REF! -> #REF! | Y34: =Z34/F34 -> 0.4 | Z34: ='CD R Investigación'!P35+'CD R Investigación'!U35+'CD R Investigación'!Z35+'CD R Investigación'!AE35+'CD R Investigación'!AJ35+'CD R Investigación'!AO35+'CD R Investigación'!AT35+'CD R Investigación'!AY35 -> 4 | AA34: ='CD R Investigación'!S35+'CD R Investigación'!X35+'CD R Investigación'!AC35+'CD R Investigación'!AH35+'CD R Investigación'!AM35+'CD R Investigación'!AR35+'CD R Investigación'!AW35+'CD R Investigación'!BB35 -> 1.76 | AB34: =AC34/F34 -> #REF! | AC34: ='CD R Desarrollo'!P35+'CD R Desarrollo'!U35+'CD R Desarrollo'!Z35+'CD R Desarrollo'!AE35+'CD R Desarrollo'!AJ35+'CD R Desarrollo'!AO35+#REF!+#REF! -> #REF! | AD34: ='CD R Desarrollo'!S35+'CD R Desarrollo'!X35+'CD R Desarrollo'!AC35+'CD R Desarrollo'!AH35+'CD R Desarrollo'!AM35+'CD R Desarrollo'!AR35+#REF!+#REF! -> #REF! | AE34: 1 | AF34: ='PL Cronograma detallado'!L131*AE34 -> 12.05 | AG34: =AF34/'PL Cronograma detallado'!M$257 -> #DIV/0! | AH34: =AG34+AH33 -> #DIV/0!
A35: 2.2.8 | B35: Realizar análisis bibliométrico en Oxford Journals, IOP Science, WoL | C35: 44676 | D35: 44695 | E35: =_xludf.DAYs(D35,C35)+1 -> #NAME? | F35: 10 | G35: =F35/F$105 -> 0.011350738 | H35: =SUM(H34,G35) -> 0.10102157 | I35: =SUM(R35,W35,Z35,AC35) -> #REF! | J35: =SUM(I35,J34) -> #REF! | K35: =J35/$J$104 -> #REF! | L35: =SUM(U35,X35,AA35,AD35) -> #REF! | M35: =SUM(L35,M34) -> #REF! | N35: =G35*AE35 -> 0.011350738 | O35: =SUM(N35,O34) -> 0.099886493 | P35: =M35/$M$93 -> #REF! | Q35: =R35/F35 -> 0 | R35: 0 | S35: L | T35: =IF(S35="L",0.68,IF(S35="JP",0.57,IF(S35="JI",0.57,IF(S35="JD",0.57,IF(S35="P",0.24,IF(S35="I",0.12,IF(S35="D",0.13))))))) -> 0.68 | U35: =T35*R35 -> 0 | V35: =W35/F35 -> #REF! | W35: ='CD R Documentación'!O36+'CD R Documentación'!T36+'CD R Documentación'!Y36+'CD R Documentación'!AD36+'CD R Documentación'!AI36+'CD R Documentación'!AN36+#REF! -> #REF! | X35: ='CD R Documentación'!R36+'CD R Documentación'!W36+'CD R Documentación'!AB36+'CD R Documentación'!AG36+'CD R Documentación'!AL36+'CD R Documentación'!AQ36+#REF! -> #REF! | Y35: =Z35/F35 -> 0.8 | Z35: ='CD R Investigación'!P36+'CD R Investigación'!U36+'CD R Investigación'!Z36+'CD R Investigación'!AE36+'CD R Investigación'!AJ36+'CD R Investigación'!AO36+'CD R Investigación'!AT36+'CD R Investigación'!AY36 -> 8 | AA35: ='CD R Investigación'!S36+'CD R Investigación'!X36+'CD R Investigación'!AC36+'CD R Investigación'!AH36+'CD R Investigación'!AM36+'CD R Investigación'!AR36+'CD R Investigación'!AW36+'CD R Investigación'!BB36 -> 3.52 | AB35: =AC35/F35 -> #REF! | AC35: ='CD R Desarrollo'!P36+'CD R Desarrollo'!U36+'CD R Desarrollo'!Z36+'CD R Desarrollo'!AE36+'CD R Desarrollo'!AJ36+'CD R Desarrollo'!AO36+#REF!+#REF! -> #REF! | AD35: ='CD R Desarrollo'!S36+'CD R Desarrollo'!X36+'CD R Desarrollo'!AC36+'CD R Desarrollo'!AH36+'CD R Desarrollo'!AM36+'CD R Desarrollo'!AR36+#REF!+#REF! -> #REF! | AE35: 1 | AF35: ='PL Cronograma detallado'!L133*AE35 -> 5.01 | AG35: =AF35/'PL Cronograma detallado'!M$257 -> #DIV/0! | AH35: =AG35+AH34 -> #DIV/0!
A36: 2.2.9 | B36: Realizar análisis bibliométrico en Scopus, WoL e IEEE Xplore | C36: 44676 | D36: 44695 | E36: =_xludf.DAYs(D36,C36)+1 -> #NAME? | F36: 10 | G36: =F36/F$105 -> 0.011350738 | H36: =SUM(H35,G36) -> 0.1123723 | I36: =SUM(R36,W36,Z36,AC36) -> #REF! | J36: =SUM(I36,J35) -> #REF! | K36: =J36/$J$104 -> #REF! | L36: =SUM(U36,X36,AA36,AD36) -> #REF! | M36: =SUM(L36,M35) -> #REF! | N36: =G36*AE36 -> 0.011350738 | O36: =SUM(N36,O35) -> 0.11123723 | P36: =M36/$M$93 -> #REF! | Q36: =R36/F36 -> 0 | R36: 0 | S36: L | T36: =IF(S36="L",0.68,IF(S36="JP",0.57,IF(S36="JI",0.57,IF(S36="JD",0.57,IF(S36="P",0.24,IF(S36="I",0.12,IF(S36="D",0.13))))))) -> 0.68 | U36: =T36*R36 -> 0 | V36: =W36/F36 -> #REF! | W36: ='CD R Documentación'!O37+'CD R Documentación'!T37+'CD R Documentación'!Y37+'CD R Documentación'!AD37+'CD R Documentación'!AI37+'CD R Documentación'!AN37+#REF! -> #REF! | X36: ='CD R Documentación'!R37+'CD R Documentación'!W37+'CD R Documentación'!AB37+'CD R Documentación'!AG37+'CD R Documentación'!AL37+'CD R Documentación'!AQ37+#REF! -> #REF! | Y36: =Z36/F36 -> 0.4 | Z36: ='CD R Investigación'!P37+'CD R Investigación'!U37+'CD R Investigación'!Z37+'CD R Investigación'!AE37+'CD R Investigación'!AJ37+'CD R Investigación'!AO37+'CD R Investigación'!AT37+'CD R Investigación'!AY37 -> 4 | AA36: ='CD R Investigación'!S37+'CD R Investigación'!X37+'CD R Investigación'!AC37+'CD R Investigación'!AH37+'CD R Investigación'!AM37+'CD R Investigación'!AR37+'CD R Investigación'!AW37+'CD R Investigación'!BB37 -> 1.76 | AB36: =AC36/F36 -> #REF! | AC36: ='CD R Desarrollo'!P37+'CD R Desarrollo'!U37+'CD R Desarrollo'!Z37+'CD R Desarrollo'!AE37+'CD R Desarrollo'!AJ37+'CD R Desarrollo'!AO37+#REF!+#REF! -> #REF! | AD36: ='CD R Desarrollo'!S37+'CD R Desarrollo'!X37+'CD R Desarrollo'!AC37+'CD R Desarrollo'!AH37+'CD R Desarrollo'!AM37+'CD R Desarrollo'!AR37+#REF!+#REF! -> #REF! | AE36: 1 | AF36: ='PL Cronograma detallado'!L134*AE36 -> 5.11 | AG36: =AF36/'PL Cronograma detallado'!M$257 -> #DIV/0! | AH36: =AG36+AH35 -> #DIV/0!
